Workbook

Sheet data
A1: record_id | B1: PatientID | C1: hospital | D1: embolias_prev | E1: fecha_prev1 | F1: fecha_prev2 | G1: fecha_prev3 | H1: fecha_diagnostico | I1: fecha_ingreso | J1: fecha_eco | K1: fecha_inicio_trat | L1: embolias_trat | M1: fecha_trat1 | N1: fecha_trat2 | O1: indicacion_cirugia | P1: fecha_cirugia | Q1: fecha_alta | R1: fecha_muerte | S1: diam_ao | T1: diam_mitral | U1: diam_ao_2 | V1: diam_mitral_2 | W1: Final | X1: IA | Y1: IA_RECORD | Z1: result | AA1: Valido | AB1: revisar medida | AC1: comentarios | AE1: Comentarios REDCAP
A2: HCSCM-1 | B2: 1226645 | C2: HCSCM | D2: 0 | H2: 2023-08-07 | I2: 2023-08-03 | J2: 2023-08-07 | K2: 2023-08-07 | L2: 1 | M2: 2023-08-07 | O2: 1 | P2: 2023-09-12 | Q2: 2023-11-28 | T2: 19 | V2: 19 | W2: 19 | Z2: 2 | AA2: TRUE | AC2: mecánica dificil de medir, hay dos que se juntan
A3: HCSCM-2 | B3: 2571256 | C3: HCSCM | D3: 1 | E3: 2022-12-12 | H3: 2022-12-14 | I3: 2022-12-12 | J3: 2022-12-15 | K3: 2022-12-12 | L3: 0 | O3: 0 | Q3: 2023-01-03 | S3: 7 | U3: 10 | W3: 7 | Z3: 6 | AA3: TRUE | AC3: bicuspide, dificil de medir
A4: HCSCM-3 | B4: 2510107 | C4: HCSCM | D4: 1 | E4: 2022-12-13 | H4: 2022-12-15 | I4: 2022-12-13 | J4: 2022-12-16 | K4: 2022-12-14 | L4: 0 | O4: 1 | P4: 2022-12-17 | Q4: 2023-01-30 | T4: 13 | V4: 13 | W4: 13 | Z4: 7 | AA4: TRUE | AC4: Se encuentra entre la válvulas
A5: HCSCM-4 | B5: 2574432 | C5: HCSCM | D5: 3 | E5: 2023-03-14 | F5: 2023-03-14 | G5: 2023-03-14 | H5: 2023-03-14 | I5: 2023-03-14 | J5: 2023-03-15 | K5: 2023-03-14 | L5: 0 | O5: 1 | P5: 2023-03-15 | Q5: 2023-04-25 | S5: 30 | U5: 28 | W5: 30 | Z5: 7 | AA5: TRUE | AC5: Muy larga, muy móvil, operada mismo día que el eco con varias previas
A6: HCSCM-5 | B6: 2638996 | C6: HCSCM | D6: 1 | E6: 2023-12-07 | H6: 2023-12-08 | I6: 2023-12-06 | J6: 2023-12-12 | K6: 2023-12-07 | L6: 0 | O6: 1 | P6: 2023-12-14 | Q6: 2024-03-12 | T6: 20 | V6: 22 | W6: 20 | Z6: 7 | AA6: TRUE | AC6: mala calidad en la imagen
A7: HCSCM-6 | B7: 2718947 | C7: HCSCM | D7: 3 | E7: 2025-03-31 | F7: 2025-03-31 | G7: 2025-03-31 | H7: 2025-03-31 | I7: 2025-03-31 | J7: 45748 | K7: 2025-03-31 | L7: 1 | M7: 2025-04-04 | O7: 1 | P7: 2025-04-03 | R7: 2025-04-07 | T7: 25 | V7: 23 | W7: 25 | Z7: 4 | AA7: TRUE | AC7: hay dos grandes
A8: HCSCM-7 | B8: 1734885 | C8: HCSCM | D8: 2 | E8: 2020-12-09 | F8: 2020-12-09 | H8: 2020-12-22 | I8: 2020-12-09 | J8: 2020-12-22 | K8: 2020-12-09 | L8: 0 | O8: 0 | Q8: 2021-01-22 | T8: 9 | V8: 8 | W8: 9 | Z8: 6 | AA8: TRUE | AC8: muy anclada a la vegetación, se distingue mal el borde
A9: HCSCM-8 | B9: 131977 | C9: HCSCM | D9: 1 | E9: 2021-02-21 | H9: 2021-02-22 | I9: 2021-02-21 | J9: 2021-02-22 | K9: 2021-02-21 | L9: 0 | O9: 1 | R9: 2021-02-24 | S9: 20 | U9: 20 | W9: 20 | Z9: 7 | AA9: TRUE | AC9: muere dos días después de la eco
A10: HCSCM-9 | B10: 1758093 | C10: HCSCM | D10: 0 | H10: 2021-02-10 | I10: 2021-02-08 | J10: 2021-02-10 | K10: 2021-02-09 | L10: 1 | M10: 2021-02-22 | O10: 1 | Q10: 2021-03-30 | S10: 15 | V10: 15 | W10: 15 | Z10: 1 | AA10: TRUE | AC10: Se indica cirtugía pero no se realiza por la fragilidad del paciente
A11: HCSCM-10 | B11: 2419082 | C11: HCSCM | D11: 2 | E11: 2020-07-01 | F11: 2020-07-01 | H11: 2020-07-03 | I11: 2020-06-29 | J11: 2020-07-04 | K11: 2020-07-03 | L11: 0 | O11: 1 | P11: 2020-07-04 | Q11: 2020-07-24 | S11: 13 | U11: 14 | W11: 13 | Z11: 7 | AA11: TRUE | AC11: Se opera el mismo día que se realiza la eco
A12: HCSCM-11 | B12: 2307720 | C12: HCSCM | D12: 1 | E12: 2021-06-19 | H12: 2021-06-20 | I12: 2021-06-18 | J12: 2021-06-21 | K12: 2021-06-21 | L12: 0 | O12: 1 | P12: 2021-06-23 | R12: 2021-08-23 | S12: 23 | U12: 24 | W12: 23 | Z12: 13 | AA12: TRUE | AC12: Cirugía realizada rápida
A13: HCSCM-12 | B13: 1855739 | C13: HCSCM | D13: 0 | H13: 2020-09-29 | I13: 2020-08-21 | J13: 2020-09-29 | K13: 2020-08-19 | L13: 1 | M13: 2020-09-24 | O13: 1 | Q13: 2020-10-26 | T13: 12 | V13: 12 | W13: 12 | Z13: 6 | AA13: TRUE | AC13: Anclada mécanica, no grande, movimiento asincopado respecto válvula, parece gran tensión
A14: HCSCM-13 | B14: 2454406 | C14: HCSCM | D14: 3 | E14: 2021-04-13 | F14: 2021-04-13 | G14: 2021-04-13 | H14: 2024-04-14 | I14: 2024-04-13 | J14: 2021-04-19 | K14: 2021-04-14 | L14: 0 | O14: 0 | Q14: 2021-05-14 | T14: 5 | V14: 13 | W14: 5 | Z14: 6 | AA14: TRUE | AB14: MMD | AC14: Medir la vegetación
A15: HCSCM-14 | B15: 1572014 | C15: HCSCM | D15: 1 | E15: 2021-04-01 | H15: 2021-04-05 | I15: 2021-03-22 | J15: 2021-04-08 | K15: 2021-04-01 | L15: 0 | O15: 1 | P15: 2021-04-09 | Q15: 2021-05-22 | T15: 8 | W15: 8 | Z15: 7 | AA15: TRUE | AB15: A | AC15: mecánica, no veo la vegetación
A16: HCSCM-15 | B16: 2400470 | C16: HCSCM | D16: 2 | E16: 2021-02-08 | F16: 2021-02-08 | H16: 2021-02-11 | I16: 2021-02-05 | J16: 2021-02-18 | K16: 2021-02-08 | L16: 0 | O16: 1 | P16: 2021-02-19 | Q16: 2021-03-21 | S16: 15 | V16: 16 | W16: 15 | Z16: 7 | AA16: TRUE | AC16: artefacto y dificil de medir
A17: HCSCM-16 | B17: 819229 | C17: HCSCM | D17: 2 | E17: 2022-06-15 | F17: 2022-06-15 | H17: 2022-06-20 | I17: 2022-06-15 | J17: 2022-06-20 | K17: 2022-06-20 | L17: 0 | O17: 1 | P17: 2022-06-29 | Q17: 2022-07-26 | S17: 11 | U17: 14 | W17: 11 | Z17: 7 | AA17: TRUE | AB17: MD | AC17: Me parece que han medido de menos
A18: HCSCM-17 | B18: 2534956 | C18: HCSCM | D18: 0 | H18: 2022-05-28 | I18: 2022-05-17 | J18: 2022-05-31 | K18: 2022-05-17 | L18: 1 | M18: 2022-05-26 | O18: 1 | Q18: 2022-06-30 | T18: 14 | V18: 15 | W18: 14 | Z18: 6 | AA18: TRUE | AC18: Grande y con movilidad, me parece un pelin más grande
A19: HCSCM-18 | B19: 2529312 | C19: HCSCM | D19: 0 | H19: 2022-04-24 | I19: 2022-04-17 | J19: 2022-04-30 | K19: 2022-04-17 | L19: 2 | M19: 2022-04-30 | N19: 2022-04-30 | O19: 1 | Q19: 2022-07-16 | T19: 5 | V19: 11 | W19: 5 | Z19: 2 | AA19: TRUE | AB19: A | AC19: Hay una masa rara muy móvil
A20: HCSCM-19 | B20: 562464 | C20: HCSCM | D20: 2 | E20: 2021-12-14 | F20: 2021-12-14 | H20: 2021-12-14 | I20: 2021-12-14 | J20: 2021-12-27 | K20: 2021-12-14 | L20: 0 | O20: 1 | P20: 2021-12-27 | Q20: 2022-01-26 | T20: 13 | V20: 14 | W20: 13 | Z20: 7 | AA20: TRUE | AC20: Parece que se va a soltar, operan el mismo día
A21: HCSCM-20 | B21: 2739127 | C21: HCSCM | D21: 0 | H21: 2025-04-09 | I21: 2025-04-04 | J21: 2025-04-22 | K21: 2025-04-04 | L21: 1 | M21: 2025-05-05 | O21: 1 | P21: 2025-04-25 | Q21: 2025-05-19 | S21: 8 | U21: 12 | W21: 8 | Z21: 4 | AA21: TRUE | AB21: MMD | AC21: Es claramente mayor de 8
A22: HCSCM-21 | B22: 1370986 | C22: HCSCM | D22: 0 | H22: 2024-01-01 | I22: 2023-12-30 | J22: 2024-01-02 | K22: 2023-12-30 | L22: 0 | O22: 1 | P22: 2024-01-03 | R22: 2024-01-23 | T22: 24 | V22: 17 | W22: 24 | Z22: 8 | AA22: TRUE | AB22: MMD | AC22: medido muy diferente
A23: HCSCM-22 | B23: 1740014 | C23: HCSCM | D23: 1 | E23: 2025-04-27 | H23: 2025-04-30 | I23: 2025-04-27 | J23: 2025-04-30 | K23: 2025-04-27 | L23: 0 | O23: 1 | R23: 2025-05-06 | T23: 9 | V23: 12 | W23: 9 | Z23: 7 | AA23: TRUE | AB23: TRUE | AC23: Hay ecografías de dos días diferentes de este paciente | AE23: En el mismo estudio se fusionaron dos estudios, realizados el día 30/4/2025 y 5/5/2025. Analicen únicamente los archivos del día 30/4/2025
A24: HCSCM-23 | B24: 219913 | C24: HCSCM | D24: 0 | H24: 2025-04-14 | I24: 2025-04-09 | J24: 2025-04-15 | K24: 2025-04-09 | L24: 1 | M24: 2025-05-14 | O24: 1 | P24: 2025-04-25 | Q24: 2025-06-06 | S24: 33 | U24: 30 | W24: 33 | Z24: 4 | AA24: TRUE | AB24: B | AC24: 10 diás sin operar y no le da una embolia y embolia 20 días más tarde tras haberse operado
A25: HCSCM-24 | B25: 1441420 | C25: HCSCM | D25: 1 | E25: 2021-07-26 | H25: 2021-08-06 | I25: 2021-07-26 | J25: 2021-08-06 | K25: 2021-08-05 | L25: 0 | O25: 1 | R25: 2021-10-30 | T25: 15 | V25: 16 | W25: 15 | Z25: 7 | AA25: TRUE | AB25: B | AC25: Hay dos en la mitral,pasa bastante hasta la muerte sin embolia con vegetación grande. Fecha de Muerte corregida por el hospital tras correo. Viendo imagen Dificil entender que no embolice
A26: HCSCM-25 | C26: HCSCM | D26: 3 | E26: 2021-04-14 | F26: 2021-04-14 | G26: 2021-04-14 | H26: 2021-04-16 | I26: 2021-04-14 | J26: 2021-04-19 | K26: 2021-04-14 | L26: 0 | O26: 0 | Q26: 2021-05-15 | T26: 8 | Z26: -1 | AA26: FALSE | AC26: Duplicado con 13, ya no hay imágenes en REDCAP (revisar las descargadas)
A27: HCSCM-26 | B27: 2624238 | C27: HCSCM | D27: 0 | H27: 2023-09-22 | I27: 2023-09-19 | J27: 2023-09-25 | K27: 2023-09-22 | L27: 0 | O27: 1 | P27: 2023-09-26 | Q27: 2023-11-02 | S27: 13 | U27: 12 | W27: 13 | Z27: 8 | AA27: TRUE | AC27: Hay dos la de la aórtica es la mas grande y cuenta un poco medirla
A28: HCSCM-27 | B28: 2059319 | C28: HCSCM | D28: 0 | H28: 2023-08-30 | I28: 2023-08-29 | J28: 2023-08-30 | K28: 2023-08-29 | L28: 0 | O28: 1 | Q28: 2023-10-16 | T28: 3 | W28: 3 | Z28: 5 | AA28: TRUE | AC28: No soy capaz de medirlo, aneurisma
A29: HCSCM-28 | B29: 560742 | C29: HCSCM | D29: 0 | H29: 2023-06-10 | I29: 2023-06-09 | J29: 2023-06-14 | K29: 2023-06-13 | L29: 0 | O29: 1 | P29: 2023-06-14 | Q29: 2023-07-04 | T29: 20 | W29: 20 | Z29: 8 | AA29: TRUE | AB29: C | AC29: Es enorme, como no puede tener embolias previas? (Bacilos Gram Negativos)
A30: HCSCM-29 | B30: 2599036 | C30: HCSCM | D30: 0 | H30: 2023-05-06 | I30: 2023-05-05 | J30: 2023-05-07 | K30: 2023-05-06 | L30: 0 | O30: 1 | P30: 2023-05-12 | R30: 2023-05-25 | S30: 15 | U30: 15 | W30: 15 | Z30: 8 | AA30: TRUE | AC30: muy dificil de medir
A31: HCSCM-30 | B31: 2575725 | C31: HCSCM | D31: 0 | H31: 2023-05-10 | I31: 2023-05-09 | J31: 2023-05-10 | K31: 2023-05-10 | L31: 0 | O31: 1 | P31: 2023-05-11 | Q31: 2023-07-12 | S31: 6 | T31: 22 | V31: 21 | W31: 22 | Z31: 8 | AA31: TRUE | AC31: sin embolias previas, grande y móvil, Hemocultivos negativos!!!
A32: HCSCM-31 | B32: 2435411 | C32: HCSCM | D32: 0 | H32: 2023-02-20 | I32: 2023-02-16 | J32: 2023-02-21 | K32: 2023-02-16 | L32: 0 | O32: 1 | P32: 2023-02-21 | Q32: 2023-05-09 | S32: 18 | Z32: -1 | AA32: FALSE | AB32: A | AC32: Ha subido tres imagénes y no son validas, Carlos dice descartar
A33: HCSCM-32 | B33: 2511968 | C33: HCSCM | D33: 0 | H33: 2022-11-07 | I33: 2022-11-02 | J33: 2022-11-18 | K33: 2022-11-02 | L33: 0 | O33: 1 | P33: 2022-11-21 | Q33: 2022-12-27 | S33: 12 | U33: 14 | W33: 12 | Z33: 8 | AA33: TRUE | AC33: Muy dificil de medir
A34: HCSCM-33 | B34: 2075675 | C34: HCSCM | D34: 0 | H34: 2023-02-13 | I34: 2023-02-13 | J34: 2023-02-13 | K34: 2023-02-13 | L34: 0 | O34: 1 | R34: 2023-03-06 | S34: 10 | U34: 10 | W34: 10 | Z34: 9 | AA34: TRUE | AC34: Muere 20 días después
A35: HCSCM-34 | B35: 2572887 | C35: HCSCM | D35: 0 | H35: 2023-01-10 | I35: 2023-01-10 | J35: 2023-01-11 | K35: 2023-01-10 | L35: 0 | O35: 1 | P35: 2023-01-11 | Q35: 2023-02-20 | S35: 8 | U35: 18 | W35: 8 | Z35: 8 | AA35: TRUE | AB35: MMD | AC35: parece muy grande
A36: HCSCM-35 | B36: 2564063 | C36: HCSCM | D36: 0 | H36: 2022-11-04 | I36: 2022-11-04 | J36: 2022-11-04 | K36: 2022-11-04 | L36: 0 | O36: 1 | P36: 2022-11-05 | Q36: 2022-11-16 | S36: 18 | U36: 15 | W36: 18 | Z36: 8 | AA36: TRUE | AC36: No se medirla
A37: HCSCM-36 | B37: 83631 | C37: HCSCM | D37: 0 | H37: 2022-08-09 | I37: 2022-08-09 | J37: 2022-08-09 | K37: 2022-08-09 | L37: 0 | O37: 1 | P37: 2022-08-10 | Q37: 2022-08-29 | S37: 16 | U37: 8 | W37: 16 | Z37: 8 | AA37: TRUE | AB37: MMD | AC37: Dificil de medir
A38: HCSCM-37 | B38: 1467340 | C38: HCSCM | D38: 0 | H38: 2021-10-10 | I38: 2021-10-10 | J38: 2021-10-13 | K38: 2021-10-10 | L38: 0 | O38: 1 | P38: 2021-10-18 | Q38: 2021-11-05 | S38: 16 | U38: 10 | W38: 16 | Z38: 8 | AA38: TRUE | AB38: MMD | AC38: Medición muy diferente
A39: HCSCM-38 | B39: 704042 | C39: HCSCM | D39: 0 | H39: 2021-12-22 | I39: 2021-12-19 | J39: 2021-12-22 | K39: 2021-12-21 | L39: 0 | O39: 1 | Q39: 2022-02-01 | T39: 10 | V39: 11 | W39: 10 | Z39: 5 | AA39: TRUE | AC39: Muy anclada
A40: HCSCM-39 | B40: 489385 | C40: HCSCM | D40: 0 | H40: 2021-09-22 | I40: 2021-09-22 | J40: 2021-09-22 | K40: 2021-09-22 | L40: 0 | O40: 0 | Q40: 2021-10-07 | S40: 28 | W40: 28 | Z40: 5 | AA40: TRUE | AB40: A MMD | AC40: No se medirlo, no es 28
...

Sheet results
B2: -1 | D2: No hay imágenes | J2: =COUNTIF(data!Z2:Z315,-1) -> 17 | R2: REVISIÓN:
B3: 1 | D3: Embolia post-eco sin previas | J3: =COUNTIF(data!Z2:Z315,1) -> 27 | R3: SM | S3: Sin medir
B4: 2 | D4: Embolia día eco sin previas | J4: =COUNTIF(data!Z2:Z315,2) -> 5 | R4: MMD | S4: Medición muy diferente
B5: 3 | D5: Embolia post-eco con embolia previa | J5: =COUNTIF(data!Z2:Z315,3) -> 6 | R5: MD | S5: Medición diferente
B6: 4 | D6: Cirugía entre o previa a eco y embolia | J6: =COUNTIF(data!Z2:Z315,4) -> 6 | R6: A | S6: Importante Revisar
B7: 5 | D7: Sin embolias previas o post ni muerte ni cirugía | J7: =COUNTIF(data!Z2:Z315,5) -> 74 | R7: B | S7: Hay que revisarlo
B8: 6 | D8: Solo embolias previas sin cirugía ni muerte | J8: =COUNTIF(data!Z2:Z315,6) -> 26 | R8: C | S8: Estaría Bien comentarlo
B9: 7 | D9: Solo previas con cirugía sin muerte | J9: =COUNTIF(data!Z2:Z315,7) -> 33
B10: 8 | D10: cirugía sin muerte sin embolias | J10: =COUNTIF(data!Z2:Z315,8) -> 59
B11: 9 | D11: muerte sin cirugía sin embolias | J11: =COUNTIF(data!Z2:Z315,9) -> 17
B12: 10 | D12: embolia previa durante el tratamiento (e ingreso) | J12: =COUNTIF(data!Z2:Z315,10) -> 3
B13: 11 | D13: Embolia despues que el eco con muerte | J13: =COUNTIF(data!Z2:Z315,11) -> 7
B14: 12 | D14: muerte sin cirugía con solo previas | J14: =COUNTIF(data!Z2:Z315,12) -> 5
B15: 13 | D15: cirugia y muerte con solo previas | J15: =COUNTIF(data!Z2:Z315,13) -> 7
B16: 14 | D16: cirugía y muerte sin embolias | J16: =COUNTIF(data!Z2:Z315,14) -> 14
Q18: =COUNTIFS(data!AA2:AA335,"<>TRUE",data!AA2:AA335,"<>FALSE") -> 0
P19: TRUE | Q19: =COUNTIF(data!AA2:AA335,TRUE) -> 296
J20: =SUM(J2:J16) -> 306 | K20: validos: | L20: =J20-J2 -> 289 | P20: FALSE | Q20: =COUNTIF(data!AA2:AA335,FALSE) -> 38
Q21: =SUM(Q19:Q20) -> 334
